Workbook

Sheet Leia-me
A1: Planilha de treino: Analista Administrativo Financeiro Jr
A2: Objetivo: simular o teste prático de Excel de um processo seletivo. Tempo sugerido: 40 minutos.
A3: Dados fictícios de uma emissora de TV e rádio fictícia. Data-base do teste: 30/04/2026 (aba Exercícios, célula B2).
A4: Legenda: células AMARELAS = preencha com fórmula. Texto AZUL = dado de entrada que você pode mudar. A primeira linha de cada tabela já vem resolvida, como exemplo.
A6: Tarefas
A7: 1. Aba Notas: preencha Fornecedor (D), Centro de custo (E) e Vencimento (G) com PROCV na aba Fornecedores. Vencimento = data da nota + prazo.
A8: 2. Aba Notas: preencha Situação (I) com SE: "Paga"; se não estiver paga e o vencimento for anterior à data-base, "Vencida"; senão, "A vencer".
A9: 3. Aba Exercícios, item 1: Previsto (PROCV na aba Orçamento, coluna Total), Realizado (SOMASES), variação em R$ e %, e situação.
A10: 4. Item 2: realizado de março/2026 por centro de custo, com SOMASES e critérios de data (DATA e FIMMÊS).
A11: 5. Item 3: contagens com CONT.SES e o valor em aberto com SOMASES.
A12: 6. Item 4: busque uma nota pelo número com PROCV.
A13: 7. Item 5: crie uma tabela dinâmica (Linhas: Centro de custo; Colunas: Status; Valores: Soma de Valor) e confira o total geral.
... A16: Gabarito: aba Gabarito. Só olhe depois de tentar!

Sheet Fornecedores
A1: Código | B1: Fornecedor | C1: Centro de custo | D1: Prazo (dias)
A2: F01 | B2: Alfa Papelaria | C2: Administrativo | D2: 30
A3: F02 | B3: Beta Tecnologia | C3: TI | D3: 45
A4: F03 | B4: Gama Eventos | C4: Marketing | D4: 15
A5: F04 | B5: Delta Limpeza | C5: Administrativo | D5: 30
A6: F05 | B6: Épsilon Transmissões | C6: Jornalismo | D6: 30
A7: F06 | B7: Zeta Gráfica | C7: Comercial | D7: 20
A8: F07 | B8: Ômega Software | C8: TI | D8: 30
A9: F08 | B9: Sigma Viagens | C9: Jornalismo | D9: 10

Sheet Notas
A1: Nota | B1: Data | C1: Código | D1: Fornecedor | E1: Centro de custo | F1: Valor | G1: Vencimento | H1: Status | I1: Situação | K1: 1. Resumo por centro de custo (jan a abr/2026)
A2: 1001 | B2: 46027 | C2: F02 | D2: =VLOOKUP(C2,'Fornecedores'!$A$2:$D$9,2,FALSE) -> Beta Tecnologia | E2: =VLOOKUP(C2,'Fornecedores'!$A$2:$D$9,3,FALSE) -> TI | F2: 2750 | G2: =B2+VLOOKUP(C2,'Fornecedores'!$A$2:$D$9,4,FALSE) -> 46072 | H2: Paga | I2: =IF(H2="Paga","Paga",IF(G2<'Exercícios'!$B$2,"Vencida","A vencer")) -> Paga
A3: 1002 | B3: 46030 | C3: F05 | F3: 5820 | H3: Paga
A4: 1003 | B4: 46033 | C4: F08 | F4: 1290 | H4: Paga
A5: 1004 | B5: 46036 | C5: F03 | F5: 3630 | H5: Aberta
A6: 1005 | B6: 46039 | C6: F06 | F6: 1860 | H6: Paga
A7: 1006 | B7: 46041 | C7: F01 | F7: 1220 | H7: Paga
A8: 1007 | B8: 46044 | C8: F04 | F8: 840 | H8: Paga
A9: 1008 | B9: 46047 | C9: F07 | F9: 2570 | H9: Paga
A10: 1009 | B10: 46050 | C10: F02 | F10: 3620 | H10: Paga
A11: 1010 | B11: 46053 | C11: F05 | F11: 3620 | H11: Paga
A12: 1011 | B12: 46056 | C12: F08 | F12: 5170 | H12: Aberta
A13: 1012 | B13: 46059 | C13: F03 | F13: 4800 | H13: Paga
A14: 1013 | B14: 46062 | C14: F06 | F14: 900 | H14: Paga
... A41: 1040 | B41: 46140 | C41: F07 | F41: 5750 | H41: Aberta

Sheet Orçamento
A1: Centro de custo | B1: Jan/26 | C1: Fev/26 | D1: Mar/26 | E1: Abr/26 | F1: Total
A2: Administrativo | B2: 2300 | C2: 2200 | D2: 3100 | E2: 3100 | F2: =SUM(B2:E2) -> 10700
A3: Comercial | B3: 1700 | C3: 800 | D3: 2300 | E3: 1300 | F3: =SUM(B3:E3) -> 6100
A4: Jornalismo | B4: 11300 | C4: 17100 | D4: 13900 | E4: 12400 | F4: =SUM(B4:E4) -> 54700
A5: Marketing | B5: 2900 | C5: 3800 | D5: 7600 | E5: 2800 | F5: =SUM(B5:E5) -> 17100
A6: TI | B6: 8900 | C6: 9700 | D6: 6300 | E6: 16100 | F6: =SUM(B6:E6) -> 41000

Sheet Exercícios
A1: Exercícios: preencha as células amarelas com fórmulas
A2: Data-base | B2: 46142
A3: Os resultados só ficam completos depois de preencher a aba Notas (tarefas 1 e 2).
A5: 1. Resumo por centro de custo (jan a abr/2026)
A6: Centro de custo | B6: Previsto | C6: Realizado | D6: Variação (R$) | E6: Variação (%) | F6: Situação
A7: Administrativo | B7: =VLOOKUP(A7,'Orçamento'!$A$2:$F$6,6,FALSE) -> 10700 | C7: =SUMIFS('Notas'!$F$2:$F$41,'Notas'!$E$2:$E$41,A7) -> 0 | D7: =C7-B7 -> -10700 | E7: =IF(B7=0,0,D7/B7) -> -1 | F7: =IF(D7>0,"Acima do previsto","Dentro do previsto") -> Dentro do previsto
A8: Comercial
A9: Jornalismo
A10: Marketing
A11: TI
A12: Total
A14: 2. Realizado de março/2026 por centro de custo
A15: Centro de custo | B15: Realizado mar/26
A16: Administrativo | B16: =SUMIFS('Notas'!$F$2:$F$41,'Notas'!$E$2:$E$41,A16,'Notas'!$B$2:$B$41,">="&DATE(2026,3,1),'Notas'!$B$2:$B$41,"<="&EOMONTH(DATE(2026,3,1),0)) -> 0
A17: Comercial
A18: Jornalismo
A19: Marketing
A20: TI
A22: 3. Contagens
A23: Notas em aberto (Status = Aberta)
A24: Notas vencidas (Situação = Vencida)
A25: % de notas vencidas sobre o total de notas
A26: Valor total em aberto
A28: 4. Busca de nota
A29: Número da nota | B29: 1017
A30: Fornecedor
A31: Valor
A32: Situação
A34: 5. Tabela dinâmica
A35: Crie numa aba nova: Inserir › Tabela Dinâmica, com a base da aba Notas.
A36: Linhas: Centro de custo · Colunas: Status · Valores: Soma de Valor.
A37: Confira: o total geral da sua tabela dinâmica deve ser igual ao valor abaixo.
A38: Total da base | B38: =SUM('Notas'!$F$2:$F$41) -> 130980

Sheet Gabarito
A1: Gabarito: só olhe depois de tentar
A3: Nota | B3: Data | C3: Código | D3: Fornecedor | E3: Centro de custo | F3: Valor | G3: Vencimento | H3: Status | I3: Situação | K3: 1. Resumo por centro de custo (jan a abr/2026)
A4: 1001 | B4: 46027 | C4: F02 | D4: =VLOOKUP(C4,'Fornecedores'!$A$2:$D$9,2,FALSE) -> Beta Tecnologia | E4: =VLOOKUP(C4,'Fornecedores'!$A$2:$D$9,3,FALSE) -> TI | F4: 2750 | G4: =B4+VLOOKUP(C4,'Fornecedores'!$A$2:$D$9,4,FALSE) -> 46072 | H4: Paga | I4: =IF(H4="Paga","Paga",IF(G4<'Exercícios'!$B$2,"Vencida","A vencer")) -> Paga | K4: Centro de custo | L4: Previsto | M4: Realizado | N4: Variação (R$) | O4: Variação (%) | P4: Situação
A5: 1002 | B5: 46030 | C5: F05 | D5: =VLOOKUP(C5,'Fornecedores'!$A$2:$D$9,2,FALSE) -> Épsilon Transmissões | E5: =VLOOKUP(C5,'Fornecedores'!$A$2:$D$9,3,FALSE) -> Jornalismo | F5: 5820 | G5: =B5+VLOOKUP(C5,'Fornecedores'!$A$2:$D$9,4,FALSE) -> 46060 | H5: Paga | I5: =IF(H5="Paga","Paga",IF(G5<'Exercícios'!$B$2,"Vencida","A vencer")) -> Paga | K5: Administrativo | L5: =VLOOKUP(K5,'Orçamento'!$A$2:$F$6,6,FALSE) -> 10700 | M5: =SUMIFS($F$4:$F$43,$E$4:$E$43,K5) -> 9690 | N5: =M5-L5 -> -1010 | O5: =IF(L5=0,0,N5/L5) -> -0.094392523 | P5: =IF(N5>0,"Acima do previsto","Dentro do previsto") -> Dentro do previsto
A6: 1003 | B6: 46033 | C6: F08 | D6: =VLOOKUP(C6,'Fornecedores'!$A$2:$D$9,2,FALSE) -> Sigma Viagens | E6: =VLOOKUP(C6,'Fornecedores'!$A$2:$D$9,3,FALSE) -> Jornalismo | F6: 1290 | G6: =B6+VLOOKUP(C6,'Fornecedores'!$A$2:$D$9,4,FALSE) -> 46043 | H6: Paga | I6: =IF(H6="Paga","Paga",IF(G6<'Exercícios'!$B$2,"Vencida","A vencer")) -> Paga | K6: Comercial | L6: =VLOOKUP(K6,'Orçamento'!$A$2:$F$6,6,FALSE) -> 6100 | M6: =SUMIFS($F$4:$F$43,$E$4:$E$43,K6) -> 6800 | N6: =M6-L6 -> 700 | O6: =IF(L6=0,0,N6/L6) -> 0.1147541 | P6: =IF(N6>0,"Acima do previsto","Dentro do previsto") -> Acima do previsto
A7: 1004 | B7: 46036 | C7: F03 | D7: =VLOOKUP(C7,'Fornecedores'!$A$2:$D$9,2,FALSE) -> Gama Eventos | E7: =VLOOKUP(C7,'Fornecedores'!$A$2:$D$9,3,FALSE) -> Marketing | F7: 3630 | G7: =B7+VLOOKUP(C7,'Fornecedores'!$A$2:$D$9,4,FALSE) -> 46051 | H7: Aberta | I7: =IF(H7="Paga","Paga",IF(G7<'Exercícios'!$B$2,"Vencida","A vencer")) -> Vencida | K7: Jornalismo | L7: =VLOOKUP(K7,'Orçamento'!$A$2:$F$6,6,FALSE) -> 54700 | M7: =SUMIFS($F$4:$F$43,$E$4:$E$43,K7) -> 52150 | N7: =M7-L7 -> -2550 | O7: =IF(L7=0,0,N7/L7) -> -0.046617916 | P7: =IF(N7>0,"Acima do previsto","Dentro do previsto") -> Dentro do previsto
A8: 1005 | B8: 46039 | C8: F06 | D8: =VLOOKUP(C8,'Fornecedores'!$A$2:$D$9,2,FALSE) -> Zeta Gráfica | E8: =VLOOKUP(C8,'Fornecedores'!$A$2:$D$9,3,FALSE) -> Comercial | F8: 1860 | G8: =B8+VLOOKUP(C8,'Fornecedores'!$A$2:$D$9,4,FALSE) -> 46059 | H8: Paga | I8: =IF(H8="Paga","Paga",IF(G8<'Exercícios'!$B$2,"Vencida","A vencer")) -> Paga | K8: Marketing | L8: =VLOOKUP(K8,'Orçamento'!$A$2:$F$6,6,FALSE) -> 17100 | M8: =SUMIFS($F$4:$F$43,$E$4:$E$43,K8) -> 21330 | N8: =M8-L8 -> 4230 | O8: =IF(L8=0,0,N8/L8) -> 0.24736842 | P8: =IF(N8>0,"Acima do previsto","Dentro do previsto") -> Acima do previsto
A9: 1006 | B9: 46041 | C9: F01 | D9: =VLOOKUP(C9,'Fornecedores'!$A$2:$D$9,2,FALSE) -> Alfa Papelaria | E9: =VLOOKUP(C9,'Fornecedores'!$A$2:$D$9,3,FALSE) -> Administrativo | F9: 1220 | G9: =B9+VLOOKUP(C9,'Fornecedores'!$A$2:$D$9,4,FALSE) -> 46071 | H9: Paga | I9: =IF(H9="Paga","Paga",IF(G9<'Exercícios'!$B$2,"Vencida","A vencer")) -> Paga | K9: TI | L9: =VLOOKUP(K9,'Orçamento'!$A$2:$F$6,6,FALSE) -> 41000 | M9: =SUMIFS($F$4:$F$43,$E$4:$E$43,K9) -> 41010 | N9: =M9-L9 -> 10 | O9: =IF(L9=0,0,N9/L9) -> 0.00024390244 | P9: =IF(N9>0,"Acima do previsto","Dentro do previsto") -> Acima do previsto
A10: 1007 | B10: 46044 | C10: F04 | D10: =VLOOKUP(C10,'Fornecedores'!$A$2:$D$9,2,FALSE) -> Delta Limpeza | E10: =VLOOKUP(C10,'Fornecedores'!$A$2:$D$9,3,FALSE) -> Administrativo | F10: 840 | G10: =B10+VLOOKUP(C10,'Fornecedores'!$A$2:$D$9,4,FALSE) -> 46074 | H10: Paga | I10: =IF(H10="Paga","Paga",IF(G10<'Exercícios'!$B$2,"Vencida","A vencer")) -> Paga | K10: Total | L10: =SUM(L5:L9) -> 129600 | M10: =SUM(M5:M9) -> 130980 | N10: =M10-L10 -> 1380 | O10: =IF(L10=0,0,N10/L10) -> 0.010648148
A11: 1008 | B11: 46047 | C11: F07 | D11: =VLOOKUP(C11,'Fornecedores'!$A$2:$D$9,2,FALSE) -> Ômega Software | E11: =VLOOKUP(C11,'Fornecedores'!$A$2:$D$9,3,FALSE) -> TI | F11: 2570 | G11: =B11+VLOOKUP(C11,'Fornecedores'!$A$2:$D$9,4,FALSE) -> 46077 | H11: Paga | I11: =IF(H11="Paga","Paga",IF(G11<'Exercícios'!$B$2,"Vencida","A vencer")) -> Paga
A12: 1009 | B12: 46050 | C12: F02 | D12: =VLOOKUP(C12,'Fornecedores'!$A$2:$D$9,2,FALSE) -> Beta Tecnologia | E12: =VLOOKUP(C12,'Fornecedores'!$A$2:$D$9,3,FALSE) -> TI | F12: 3620 | G12: =B12+VLOOKUP(C12,'Fornecedores'!$A$2:$D$9,4,FALSE) -> 46095 | H12: Paga | I12: =IF(H12="Paga","Paga",IF(G12<'Exercícios'!$B$2,"Vencida","A vencer")) -> Paga | K12: 2. Realizado de março/2026 por centro de custo
A13: 1010 | B13: 46053 | C13: F05 | D13: =VLOOKUP(C13,'Fornecedores'!$A$2:$D$9,2,FALSE) -> Épsilon Transmissões | E13: =VLOOKUP(C13,'Fornecedores'!$A$2:$D$9,3,FALSE) -> Jornalismo | F13: 3620 | G13: =B13+VLOOKUP(C13,'Fornecedores'!$A$2:$D$9,4,FALSE) -> 46083 | H13: Paga | I13: =IF(H13="Paga","Paga",IF(G13<'Exercícios'!$B$2,"Vencida","A vencer")) -> Paga | K13: Centro de custo | L13: Realizado mar/26
A14: 1011 | B14: 46056 | C14: F08 | D14: =VLOOKUP(C14,'Fornecedores'!$A$2:$D$9,2,FALSE) -> Sigma Viagens | E14: =VLOOKUP(C14,'Fornecedores'!$A$2:$D$9,3,FALSE) -> Jornalismo | F14: 5170 | G14: =B14+VLOOKUP(C14,'Fornecedores'!$A$2:$D$9,4,FALSE) -> 46066 | H14: Aberta | I14: =IF(H14="Paga","Paga",IF(G14<'Exercícios'!$B$2,"Vencida","A vencer")) -> Vencida | K14: Administrativo | L14: =SUMIFS($F$4:$F$43,$E$4:$E$43,K14,$B$4:$B$43,">="&DATE(2026,3,1),$B$4:$B$43,"<="&EOMONTH(DATE(2026,3,1),0)) -> 2820
A15: 1012 | B15: 46059 | C15: F03 | D15: =VLOOKUP(C15,'Fornecedores'!$A$2:$D$9,2,FALSE) -> Gama Eventos | E15: =VLOOKUP(C15,'Fornecedores'!$A$2:$D$9,3,FALSE) -> Marketing | F15: 4800 | G15: =B15+VLOOKUP(C15,'Fornecedores'!$A$2:$D$9,4,FALSE) -> 46074 | H15: Paga | I15: =IF(H15="Paga","Paga",IF(G15<'Exercícios'!$B$2,"Vencida","A vencer")) -> Paga | K15: Comercial | L15: =SUMIFS($F$4:$F$43,$E$4:$E$43,K15,$B$4:$B$43,">="&DATE(2026,3,1),$B$4:$B$43,"<="&EOMONTH(DATE(2026,3,1),0)) -> 2600
A16: 1013 | B16: 46062 | C16: F06 | D16: =VLOOKUP(C16,'Fornecedores'!$A$2:$D$9,2,FALSE) -> Zeta Gráfica | E16: =VLOOKUP(C16,'Fornecedores'!$A$2:$D$9,3,FALSE) -> Comercial | F16: 900 | G16: =B16+VLOOKUP(C16,'Fornecedores'!$A$2:$D$9,4,FALSE) -> 46082 | H16: Paga | I16: =IF(H16="Paga","Paga",IF(G16<'Exercícios'!$B$2,"Vencida","A vencer")) -> Paga | K16: Jornalismo | L16: =SUMIFS($F$4:$F$43,$E$4:$E$43,K16,$B$4:$B$43,">="&DATE(2026,3,1),$B$4:$B$43,"<="&EOMONTH(DATE(2026,3,1),0)) -> 13280
A17: 1014 | B17: 46065 | C17: F01 | D17: =VLOOKUP(C17,'Fornecedores'!$A$2:$D$9,2,FALSE) -> Alfa Papelaria | E17: =VLOOKUP(C17,'Fornecedores'!$A$2:$D$9,3,FALSE) -> Administrativo | F17: 830 | G17: =B17+VLOOKUP(C17,'Fornecedores'!$A$2:$D$9,4,FALSE) -> 46095 | H17: Paga | I17: =IF(H17="Paga","Paga",IF(G17<'Exercícios'!$B$2,"Vencida","A vencer")) -> Paga | K17: Marketing | L17: =SUMIFS($F$4:$F$43,$E$4:$E$43,K17,$B$4:$B$43,">="&DATE(2026,3,1),$B$4:$B$43,"<="&EOMONTH(DATE(2026,3,1),0)) -> 9440
A18: 1015 | B18: 46068 | C18: F04 | D18: =VLOOKUP(C18,'Fornecedores'!$A$2:$D$9,2,FALSE) -> Delta Limpeza | E18: =VLOOKUP(C18,'Fornecedores'!$A$2:$D$9,3,FALSE) -> Administrativo | F18: 1130 | G18: =B18+VLOOKUP(C18,'Fornecedores'!$A$2:$D$9,4,FALSE) -> 46098 | H18: Paga | I18: =IF(H18="Paga","Paga",IF(G18<'Exercícios'!$B$2,"Vencida","A vencer")) -> Paga | K18: TI | L18: =SUMIFS($F$4:$F$43,$E$4:$E$43,K18,$B$4:$B$43,">="&DATE(2026,3,1),$B$4:$B$43,"<="&EOMONTH(DATE(2026,3,1),0)) -> 6290
A19: 1016 | B19: 46070 | C19: F07 | D19: =VLOOKUP(C19,'Fornecedores'!$A$2:$D$9,2,FALSE) -> Ômega Software | E19: =VLOOKUP(C19,'Fornecedores'!$A$2:$D$9,3,FALSE) -> TI | F19: 4360 | G19: =B19+VLOOKUP(C19,'Fornecedores'!$A$2:$D$9,4,FALSE) -> 46100 | H19: Paga | I19: =IF(H19="Paga","Paga",IF(G19<'Exercícios'!$B$2,"Vencida","A vencer")) -> Paga
A20: 1017 | B20: 46073 | C20: F02 | D20: =VLOOKUP(C20,'Fornecedores'!$A$2:$D$9,2,FALSE) -> Beta Tecnologia | E20: =VLOOKUP(C20,'Fornecedores'!$A$2:$D$9,3,FALSE) -> TI | F20: 5310 | G20: =B20+VLOOKUP(C20,'Fornecedores'!$A$2:$D$9,4,FALSE) -> 46118 | H20: Paga | I20: =IF(H20="Paga","Paga",IF(G20<'Exercícios'!$B$2,"Vencida","A vencer")) -> Paga | K20: 3. Contagens
A21: 1018 | B21: 46076 | C21: F05 | D21: =VLOOKUP(C21,'Fornecedores'!$A$2:$D$9,2,FALSE) -> Épsilon Transmissões | E21: =VLOOKUP(C21,'Fornecedores'!$A$2:$D$9,3,FALSE) -> Jornalismo | F21: 6750 | G21: =B21+VLOOKUP(C21,'Fornecedores'!$A$2:$D$9,4,FALSE) -> 46106 | H21: Aberta | I21: =IF(H21="Paga","Paga",IF(G21<'Exercícios'!$B$2,"Vencida","A vencer")) -> Vencida | K21: Notas em aberto | L21: =COUNTIFS($H$4:$H$43,"Aberta") -> 13
A22: 1019 | B22: 46079 | C22: F08 | D22: =VLOOKUP(C22,'Fornecedores'!$A$2:$D$9,2,FALSE) -> Sigma Viagens | E22: =VLOOKUP(C22,'Fornecedores'!$A$2:$D$9,3,FALSE) -> Jornalismo | F22: 4380 | G22: =B22+VLOOKUP(C22,'Fornecedores'!$A$2:$D$9,4,FALSE) -> 46089 | H22: Paga | I22: =IF(H22="Paga","Paga",IF(G22<'Exercícios'!$B$2,"Vencida","A vencer")) -> Paga | K22: Notas vencidas | L22: =COUNTIFS($I$4:$I$43,"Vencida") -> 3
A23: 1020 | B23: 46082 | C23: F03 | D23: =VLOOKUP(C23,'Fornecedores'!$A$2:$D$9,2,FALSE) -> Gama Eventos | E23: =VLOOKUP(C23,'Fornecedores'!$A$2:$D$9,3,FALSE) -> Marketing | F23: 4780 | G23: =B23+VLOOKUP(C23,'Fornecedores'!$A$2:$D$9,4,FALSE) -> 46097 | H23: Paga | I23: =IF(H23="Paga","Paga",IF(G23<'Exercícios'!$B$2,"Vencida","A vencer")) -> Paga | K23: % de notas vencidas | L23: =L22/COUNTA($A$4:$A$43) -> 0.075
A24: 1021 | B24: 46085 | C24: F06 | D24: =VLOOKUP(C24,'Fornecedores'!$A$2:$D$9,2,FALSE) -> Zeta Gráfica | E24: =VLOOKUP(C24,'Fornecedores'!$A$2:$D$9,3,FALSE) -> Comercial | F24: 2030 | G24: =B24+VLOOKUP(C24,'Fornecedores'!$A$2:$D$9,4,FALSE) -> 46105 | H24: Paga | I24: =IF(H24="Paga","Paga",IF(G24<'Exercícios'!$B$2,"Vencida","A vencer")) -> Paga | K24: Valor total em aberto | L24: =SUMIFS($F$4:$F$43,$H$4:$H$43,"Aberta") -> 49440
A25: 1022 | B25: 46088 | C25: F01 | D25: =VLOOKUP(C25,'Fornecedores'!$A$2:$D$9,2,FALSE) -> Alfa Papelaria | E25: =VLOOKUP(C25,'Fornecedores'!$A$2:$D$9,3,FALSE) -> Administrativo | F25: 480 | G25: =B25+VLOOKUP(C25,'Fornecedores'!$A$2:$D$9,4,FALSE) -> 46118 | H25: Paga | I25: =IF(H25="Paga","Paga",IF(G25<'Exercícios'!$B$2,"Vencida","A vencer")) -> Paga
A26: 1023 | B26: 46091 | C26: F04 | D26: =VLOOKUP(C26,'Fornecedores'!$A$2:$D$9,2,FALSE) -> Delta Limpeza | E26: =VLOOKUP(C26,'Fornecedores'!$A$2:$D$9,3,FALSE) -> Administrativo | F26: 920 | G26: =B26+VLOOKUP(C26,'Fornecedores'!$A$2:$D$9,4,FALSE) -> 46121 | H26: Paga | I26: =IF(H26="Paga","Paga",IF(G26<'Exercícios'!$B$2,"Vencida","A vencer")) -> Paga | K26: 4. Busca de nota
A27: 1024 | B27: 46094 | C27: F07 | D27: =VLOOKUP(C27,'Fornecedores'!$A$2:$D$9,2,FALSE) -> Ômega Software | E27: =VLOOKUP(C27,'Fornecedores'!$A$2:$D$9,3,FALSE) -> TI | F27: 2270 | G27: =B27+VLOOKUP(C27,'Fornecedores'!$A$2:$D$9,4,FALSE) -> 46124 | H27: Paga | I27: =IF(H27="Paga","Paga",IF(G27<'Exercícios'!$B$2,"Vencida","A vencer")) -> Paga | K27: Número da nota | L27: ='Exercícios'!$B$29 -> 1017
A28: 1025 | B28: 46097 | C28: F02 | D28: =VLOOKUP(C28,'Fornecedores'!$A$2:$D$9,2,FALSE) -> Beta Tecnologia | E28: =VLOOKUP(C28,'Fornecedores'!$A$2:$D$9,3,FALSE) -> TI | F28: 4020 | G28: =B28+VLOOKUP(C28,'Fornecedores'!$A$2:$D$9,4,FALSE) -> 46142 | H28: Aberta | I28: =IF(H28="Paga","Paga",IF(G28<'Exercícios'!$B$2,"Vencida","A vencer")) -> A vencer | K28: Fornecedor | L28: =VLOOKUP(L27,$A$4:$I$43,4,FALSE) -> Beta Tecnologia
A29: 1026 | B29: 46099 | C29: F05 | D29: =VLOOKUP(C29,'Fornecedores'!$A$2:$D$9,2,FALSE) -> Épsilon Transmissões | E29: =VLOOKUP(C29,'Fornecedores'!$A$2:$D$9,3,FALSE) -> Jornalismo | F29: 6920 | G29: =B29+VLOOKUP(C29,'Fornecedores'!$A$2:$D$9,4,FALSE) -> 46129 | H29: Paga | I29: =IF(H29="Paga","Paga",IF(G29<'Exercícios'!$B$2,"Vencida","A vencer")) -> Paga | K29: Valor | L29: =VLOOKUP(L27,$A$4:$I$43,6,FALSE) -> 5310
A30: 1027 | B30: 46102 | C30: F08 | D30: =VLOOKUP(C30,'Fornecedores'!$A$2:$D$9,2,FALSE) -> Sigma Viagens | E30: =VLOOKUP(C30,'Fornecedores'!$A$2:$D$9,3,FALSE) -> Jornalismo | F30: 6360 | G30: =B30+VLOOKUP(C30,'Fornecedores'!$A$2:$D$9,4,FALSE) -> 46112 | H30: Paga | I30: =IF(H30="Paga","Paga",IF(G30<'Exercícios'!$B$2,"Vencida","A vencer")) -> Paga | K30: Situação | L30: =VLOOKUP(L27,$A$4:$I$43,9,FALSE) -> Paga
A31: 1028 | B31: 46105 | C31: F03 | D31: =VLOOKUP(C31,'Fornecedores'!$A$2:$D$9,2,FALSE) -> Gama Eventos | E31: =VLOOKUP(C31,'Fornecedores'!$A$2:$D$9,3,FALSE) -> Marketing | F31: 4660 | G31: =B31+VLOOKUP(C31,'Fornecedores'!$A$2:$D$9,4,FALSE) -> 46120 | H31: Paga | I31: =IF(H31="Paga","Paga",IF(G31<'Exercícios'!$B$2,"Vencida","A vencer")) -> Paga
A32: 1029 | B32: 46108 | C32: F06 | D32: =VLOOKUP(C32,'Fornecedores'!$A$2:$D$9,2,FALSE) -> Zeta Gráfica | E32: =VLOOKUP(C32,'Fornecedores'!$A$2:$D$9,3,FALSE) -> Comercial | F32: 570 | G32: =B32+VLOOKUP(C32,'Fornecedores'!$A$2:$D$9,4,FALSE) -> 46128 | H32: Paga | I32: =IF(H32="Paga","Paga",IF(G32<'Exercícios'!$B$2,"Vencida","A vencer")) -> Paga | K32: 5. Tabela dinâmica esperada (Soma de Valor)
A33: 1030 | B33: 46111 | C33: F01 | D33: =VLOOKUP(C33,'Fornecedores'!$A$2:$D$9,2,FALSE) -> Alfa Papelaria | E33: =VLOOKUP(C33,'Fornecedores'!$A$2:$D$9,3,FALSE) -> Administrativo | F33: 1420 | G33: =B33+VLOOKUP(C33,'Fornecedores'!$A$2:$D$9,4,FALSE) -> 46141 | H33: Paga | I33: =IF(H33="Paga","Paga",IF(G33<'Exercícios'!$B$2,"Vencida","A vencer")) -> Paga | K33: Centro de custo | L33: Aberta | M33: Paga | N33: Total geral
A34: 1031 | B34: 46114 | C34: F04 | D34: =VLOOKUP(C34,'Fornecedores'!$A$2:$D$9,2,FALSE) -> Delta Limpeza | E34: =VLOOKUP(C34,'Fornecedores'!$A$2:$D$9,3,FALSE) -> Administrativo | F34: 740 | G34: =B34+VLOOKUP(C34,'Fornecedores'!$A$2:$D$9,4,FALSE) -> 46144 | H34: Aberta | I34: =IF(H34="Paga","Paga",IF(G34<'Exercícios'!$B$2,"Vencida","A vencer")) -> A vencer | K34: Administrativo | L34: =SUMIFS($F$4:$F$43,$E$4:$E$43,$K34,$H$4:$H$43,L$33) -> 2850 | M34: =SUMIFS($F$4:$F$43,$E$4:$E$43,$K34,$H$4:$H$43,M$33) -> 6840 | N34: =L34+M34 -> 9690
A35: 1032 | B35: 46117 | C35: F07 | D35: =VLOOKUP(C35,'Fornecedores'!$A$2:$D$9,2,FALSE) -> Ômega Software | E35: =VLOOKUP(C35,'Fornecedores'!$A$2:$D$9,3,FALSE) -> TI | F35: 4880 | G35: =B35+VLOOKUP(C35,'Fornecedores'!$A$2:$D$9,4,FALSE) -> 46147 | H35: Aberta | I35: =IF(H35="Paga","Paga",IF(G35<'Exercícios'!$B$2,"Vencida","A vencer")) -> A vencer | K35: Comercial | L35: =SUMIFS($F$4:$F$43,$E$4:$E$43,$K35,$H$4:$H$43,L$33) -> 1440 | M35: =SUMIFS($F$4:$F$43,$E$4:$E$43,$K35,$H$4:$H$43,M$33) -> 5360 | N35: =L35+M35 -> 6800
A36: 1033 | B36: 46120 | C36: F02 | D36: =VLOOKUP(C36,'Fornecedores'!$A$2:$D$9,2,FALSE) -> Beta Tecnologia | E36: =VLOOKUP(C36,'Fornecedores'!$A$2:$D$9,3,FALSE) -> TI | F36: 5480 | G36: =B36+VLOOKUP(C36,'Fornecedores'!$A$2:$D$9,4,FALSE) -> 46165 | H36: Aberta | I36: =IF(H36="Paga","Paga",IF(G36<'Exercícios'!$B$2,"Vencida","A vencer")) -> A vencer | K36: Jornalismo | L36: =SUMIFS($F$4:$F$43,$E$4:$E$43,$K36,$H$4:$H$43,L$33) -> 17930 | M36: =SUMIFS($F$4:$F$43,$E$4:$E$43,$K36,$H$4:$H$43,M$33) -> 34220 | N36: =L36+M36 -> 52150
A37: 1034 | B37: 46123 | C37: F05 | D37: =VLOOKUP(C37,'Fornecedores'!$A$2:$D$9,2,FALSE) -> Épsilon Transmissões | E37: =VLOOKUP(C37,'Fornecedores'!$A$2:$D$9,3,FALSE) -> Jornalismo | F37: 6010 | G37: =B37+VLOOKUP(C37,'Fornecedores'!$A$2:$D$9,4,FALSE) -> 46153 | H37: Aberta | I37: =IF(H37="Paga","Paga",IF(G37<'Exercícios'!$B$2,"Vencida","A vencer")) -> A vencer | K37: Marketing | L37: =SUMIFS($F$4:$F$43,$E$4:$E$43,$K37,$H$4:$H$43,L$33) -> 7090 | M37: =SUMIFS($F$4:$F$43,$E$4:$E$43,$K37,$H$4:$H$43,M$33) -> 14240 | N37: =L37+M37 -> 21330
A38: 1035 | B38: 46126 | C38: F08 | D38: =VLOOKUP(C38,'Fornecedores'!$A$2:$D$9,2,FALSE) -> Sigma Viagens | E38: =VLOOKUP(C38,'Fornecedores'!$A$2:$D$9,3,FALSE) -> Jornalismo | F38: 5830 | G38: =B38+VLOOKUP(C38,'Fornecedores'!$A$2:$D$9,4,FALSE) -> 46136 | H38: Paga | I38: =IF(H38="Paga","Paga",IF(G38<'Exercícios'!$B$2,"Vencida","A vencer")) -> Paga | K38: TI | L38: =SUMIFS($F$4:$F$43,$E$4:$E$43,$K38,$H$4:$H$43,L$33) -> 20130 | M38: =SUMIFS($F$4:$F$43,$E$4:$E$43,$K38,$H$4:$H$43,M$33) -> 20880 | N38: =L38+M38 -> 41010
A39: 1036 | B39: 46128 | C39: F03 | D39: =VLOOKUP(C39,'Fornecedores'!$A$2:$D$9,2,FALSE) -> Gama Eventos | E39: =VLOOKUP(C39,'Fornecedores'!$A$2:$D$9,3,FALSE) -> Marketing | F39: 3460 | G39: =B39+VLOOKUP(C39,'Fornecedores'!$A$2:$D$9,4,FALSE) -> 46143 | H39: Aberta | I39: =IF(H39="Paga","Paga",IF(G39<'Exercícios'!$B$2,"Vencida","A vencer")) -> A vencer | K39: Total geral | L39: =SUM(L34:L38) -> 49440 | M39: =SUM(M34:M38) -> 81540 | N39: =SUM(N34:N38) -> 130980
A40: 1037 | B40: 46131 | C40: F06 | D40: =VLOOKUP(C40,'Fornecedores'!$A$2:$D$9,2,FALSE) -> Zeta Gráfica | E40: =VLOOKUP(C40,'Fornecedores'!$A$2:$D$9,3,FALSE) -> Comercial | F40: 1440 | G40: =B40+VLOOKUP(C40,'Fornecedores'!$A$2:$D$9,4,FALSE) -> 46151 | H40: Aberta | I40: =IF(H40="Paga","Paga",IF(G40<'Exercícios'!$B$2,"Vencida","A vencer")) -> A vencer
A41: 1038 | B41: 46134 | C41: F01 | D41: =VLOOKUP(C41,'Fornecedores'!$A$2:$D$9,2,FALSE) -> Alfa Papelaria | E41: =VLOOKUP(C41,'Fornecedores'!$A$2:$D$9,3,FALSE) -> Administrativo | F41: 1390 | G41: =B41+VLOOKUP(C41,'Fornecedores'!$A$2:$D$9,4,FALSE) -> 46164 | H41: Aberta | I41: =IF(H41="Paga","Paga",IF(G41<'Exercícios'!$B$2,"Vencida","A vencer")) -> A vencer
...
